Workbook
Name TableGone: Table!$B$7
Name TableSpan: Table!$B$2:$B$8
Name TotalsCell: TableTotals!$B$9
Name TotalsSpan: TableTotals!$B$2:$B$8

Sheet Pairs
A1: v | B1: m
A2: 1 | B2: first
A3: 1 | B3: second
A5: v | B5: m
A6: 1 | B6: first
A7: =1+2^-52 -> 1 | B7: second
A9: v | B9: m
A10: 0.1 | B10: first
A11: =0.3-0.2 -> 0.1 | B11: second
A13: v | B13: m
A14: 1 | B14: first
A15: 1 | B15: second
A17: v | B17: m
A18: 43845 | B18: first
A19: 43845 | B19: second
A21: v | B21: m
A22: 43845 | B22: first
A23: 43845 | B23: second
A25: v | B25: m
A26: 1.2345679 | B26: first
A27: 1.2345679 | B27: second
A29: v | B29: m
A30: 12345678901 | B30: first
A31: 12345678902 | B31: second
A33: v | B33: m
A34: 123456789012 | B34: first
A35: 123456789013 | B35: second
A37: v | B37: m
A38: 1.5 | B38: first
A39: 2 | B39: second
A41: v | B41: m
A42: 2 | B42: first
A43: 2 | B43: second
A45: v | B45: m
A46: 1.5 | B46: first
A47: 1.5 | B47: second
A49: v | B49: m
A50: 1e+20 | B50: first
A51: 1e+20 | B51: second
A53: v | B53: m
...

Sheet Keys
A1: k | B1: n | C1: c | E1: out
A2: x | B2: 1 | C2: c1 | E2: o1
A3: x | B3: 2 | C3: c2 | E3: o2
A4: y | B4: 1 | C4: c3 | E4: o3
A5: x | B5: 1 | C5: c4 | E5: o4
A6: y | B6: 1 | C6: c5 | E6: o5
A7: z | B7: 3 | C7: c6 | E7: o6
A10: =A5&B5&C5 -> x1c4 | E10: =COUNTA(A2:A7) -> 6
A11: =SUM(B2:B7) -> 9

Sheet Moves
A1: k | B1: f | C1: fmt
A2: a | B2: =ROW()&A2 -> 2a | C2: 20
A3: a | B3: =ROW()&A3 -> 3a | C3: 30
A4: b | B4: =ROW()&A4 -> 4b | C4: 40
A5: a | B5: =ROW()&A5 -> 5a | C5: 50
A6: c | B6: =ROW()&A6 -> 6c | C6: 60
A7: b | B7: =ROW()&A7 -> 7b | C7: 70
A8: d | B8: =ROW()&A8 -> 8d | C8: 80
A12: =C3 -> 30

Sheet Partial
A1: k | B1: n | C1: m
A2: a | B2: 1 | C2: m1
A3: b | B3: 2 | C3: m2
A4: a | B4: 3 | C4: m3
A5: c | B5: 4 | C5: m4
A6: b | B6: 5 | C6: m5
A7: d | B7: 6 | C7: m6

Sheet NoHeader
A1: a | B1: 1
A2: b | B2: 2
A3: a | B3: 3
A4: c | B4: 4
A5: b | B5: 5

Sheet Hidden
A1: k | B1: n
A2: a | B2: 1
A3: b | B3: 2
A4: a | B4: 3
A5: c | B5: 4
A6: b | B6: 5
A7: a | B7: 6

Sheet Merged
A1: k | B1: n
A2: a | B2: 1
A3: a | B3: 2
A4: b | B4: 3

Sheet ArrayRows
A1: k | B1: n
A2: a | B2: 1 | C2: {=B2:B3*2} -> 2
A3: a | B3: 2 | C3: 4
A4: b | B4: 3

Sheet ArrayStays
A1: k | B1: n
A2: a | B2: 1 | C2: {=SUM(B2:B5*1)} -> 10
A3: a | B3: 2
A4: b | B4: 3
A5: c | B5: 4

Sheet ArrayRemoved
A1: k | B1: n
A2: a | B2: 1
A3: a | B3: 2 | C3: {=SUM(B2:B5*1)} -> 10
A4: b | B4: 3
A5: c | B5: 4

Sheet ArrayMoves
A1: k | B1: n
A2: a | B2: 1
A3: a | B3: 2
A4: b | B4: 3 | C4: {=SUM(B2:B5*1)} -> 10
A5: c | B5: 4

Sheet Total
A1: k | B1: n
A2: a | B2: 1
A3: a | B3: 2
A4: b | B4: 3
A5: c | B5: 4 | C5: =SUM(B2:B5) -> 10

Sheet TotalAway
A1: k | B1: n
A2: a | B2: 1
A3: a | B3: 2
A4: b | B4: 3
A5: c | B5: 4 | C5: =SUM(D1:D2) -> 0

Sheet NotTotal
A1: k | B1: n
A2: a | B2: 1
A3: a | B3: 2
A4: b | B4: 3
A5: c | B5: 4 | C5: =B5*2 -> 8

Sheet EmptyBelow
A1: k | B1: n
A2: a | B2: 1
A3: b | B3: 2
A4: a | B4: 3
A5: c | B5: 4
A6: b | B6: 5

Sheet Table
A1: k | B1: n | C1: m | E1: out | H1: =B7 -> 6
A2: a | B2: 1 | C2: m1 | E2: o1 | H2: =SUM(B2:B8) -> 28
A3: a | B3: 2 | C3: m2 | E3: o2 | H3: =SUM(B3:B8) -> 27
A4: b | B4: 3 | C4: m3 | E4: o3 | H4: =SUM(A2:B8) -> 28
A5: a | B5: 4 | C5: m4 | E5: o4 | H5: =SUM(A1:C8) -> 98
A6: c | B6: 5 | C6: m5 | E6: o5 | H6: =SUM(B1:B8) -> 28
A7: b | B7: 6 | C7: m6 | E7: o6 | H7: =SUM(B$2:B$8) -> 28
A8: d | B8: 7 | C8: =B8*10 -> 70 | E8: o7 | H8: =SUM(A2:E8) -> 98
H9: =SUM(B6:B8) -> 18
H10: =SUM(B4:B10) -> 25
H11: =SUM(A8:E8) -> 77
A12: below | B12: =SUM(B2:B8) -> 28 | C12: =SUM(TTable[n]) -> 28 | D12: =B5 -> 4 | H12: =SUM(B8:B9) -> 7
H13: =$B$5 -> 4

Sheet TableTotals
A1: k | B1: n | C1: m | E1: out | H1: =B6 -> 5
A2: a | B2: 1 | C2: m1 | E2: o1 | H2: =B7 -> 6
A3: a | B3: 2 | C3: m2 | E3: o2 | H3: =B8 -> 7
A4: b | B4: 3 | C4: m3 | E4: o3 | H4: =B9 -> 28
A5: a | B5: 4 | C5: m4 | E5: o4 | H5: =SUM(B2:B8) -> 28
A6: c | B6: 5 | C6: m5 | E6: o5 | H6: =SUM(B3:B8) -> 27
A7: b | B7: 6 | C7: m6 | E7: o6 | H7: =SUM(A1:C8) -> 98
A8: d | B8: 7 | C8: =B8*10 -> 70 | E8: o7 | H8: =SUM(B2:B9) -> 56
A9: Total | B9: =SUBTOTAL(109,TTableTotals[n]) -> 28 | C9: =SUBTOTAL(103,TTableTotals[m]) -> 7 | H9: =SUM(A1:C9) -> 133
H10: =SUM(B8:B9) -> 35
H11: =SUM(B7:B9) -> 41
A12: below | B12: =SUM(B2:B8) -> 28 | C12: =SUM(TTableTotals[n]) -> 28 | D12: =B5 -> 4 | H12: =SUM(B6:B9) -> 46
H13: =SUM(B9:B12) -> 56
H14: =SUM(B8:B10) -> 35
H15: =SUM(B4:B10) -> 53
H16: =SUM(A8:E8) -> 77
H17: =SUM(A6:D8) -> 88
H18: =SUM(A9:E9) -> 35
H19: =SUM(A6:E9) -> 123
H20: =SUM(A8:C8) -> 77
H21: =SUM(A7:C9) -> 118
H22: =SUM(A5:C9) -> 127

Sheet TableTotalsShapes
A1: k | B1: n | C1: m | E1: out
A2: a | B2: 1 | C2: m1 | E2: o1
A3: a | B3: 2 | C3: m2 | E3: o2
A4: b | B4: 3 | C4: m3 | E4: o3
A5: a | B5: 4 | C5: m4 | E5: o4
A6: c | B6: 5 | C6: m5 | E6: o5
A7: b | B7: 6 | C7: m6 | E7: o6
A8: d | B8: 7 | C8: m7 | E8: o7
A9: Total | B9: =SUBTOTAL(109,TTableTotalsShapes[n]) -> 28 | C9: =SUBTOTAL(103,TTableTotalsShapes[m]) -> 7
A12: below | B12: =SUM(B2:B8) -> 28 | C12: =SUM(TTableTotalsShapes[n]) -> 28 | D12: =B5 -> 4

Sheet Reader
A1: =SUM(Table!B2:B8) -> 28
A2: =Table!B7 -> 6
A3: =SUM(TableTotals!B2:B8) -> 28
A4: =TableTotals!B9 -> 28
A5: =SUM(TableTotals!A1:C9) -> 133
A6: =TableTotals!B7 -> 6

Sheet TableInner
A1: k | B1: n | C1: m | E1: out
A2: a | B2: 1 | C2: m1 | E2: o1
A3: a | B3: 2 | C3: m2 | E3: o2
A4: b | B4: 3 | C4: m3 | E4: o3
A5: a | B5: 4 | C5: m4 | E5: o4
A6: c | B6: 5 | C6: m5 | E6: o5
A7: b | B7: 6 | C7: m6 | E7: o6
A8: d | B8: 7 | C8: m7 | E8: o7
A12: below | B12: =SUM(B2:B8) -> 28 | C12: =SUM(TTableInner[n]) -> 28 | D12: =B5 -> 4

Sheet TableCell
A1: k | B1: n | C1: m | E1: out
A2: a | B2: 1 | C2: m1 | E2: o1
A3: a | B3: 2 | C3: m2 | E3: o2
A4: b | B4: 3 | C4: m3 | E4: o3
A5: a | B5: 4 | C5: m4 | E5: o4
A6: c | B6: 5 | C6: m5 | E6: o5
A7: b | B7: 6 | C7: m6 | E7: o6
A8: d | B8: 7 | C8: m7 | E8: o7
A12: below | B12: =SUM(B2:B8) -> 28 | C12: =SUM(TTableCell[n]) -> 28 | D12: =B5 -> 4

Sheet TableNoHeaderAsked
A1: k | B1: n | C1: m | E1: out
A2: a | B2: 1 | C2: m1 | E2: o1
A3: a | B3: 2 | C3: m2 | E3: o2
A4: b | B4: 3 | C4: m3 | E4: o3
A5: a | B5: 4 | C5: m4 | E5: o4
A6: c | B6: 5 | C6: m5 | E6: o5
A7: b | B7: 6 | C7: m6 | E7: o6
A8: d | B8: 7 | C8: m7 | E8: o7
A12: below | B12: =SUM(B2:B8) -> 28 | C12: =SUM(TTableNoHeaderAsked[n]) -> 28 | D12: =B5 -> 4

Sheet TableTotalsRow
A1: k | B1: n | C1: m | E1: out
A2: a | B2: 1 | C2: m1 | E2: o1
A3: a | B3: 2 | C3: m2 | E3: o2
A4: b | B4: 3 | C4: m3 | E4: o3
A5: a | B5: 4 | C5: m4 | E5: o4
A6: c | B6: 5 | C6: m5 | E6: o5
A7: b | B7: 6 | C7: m6 | E7: o6
A8: d | B8: 7 | C8: m7 | E8: o7
A9: Total | B9: =SUBTOTAL(109,TTableTotalsRow[n]) -> 28 | C9: =SUBTOTAL(103,TTableTotalsRow[m]) -> 7
A12: below | B12: =SUM(B2:B8) -> 28 | C12: =SUM(TTableTotalsRow[n]) -> 28 | D12: =B5 -> 4

Sheet TableCalc
A1: k | B1: n | C1: m | D1: calc | F1: out
A2: a | B2: 1 | C2: m1 | D2: =TTableCalc[[#This Row],[k]]&TTableCalc[[#This Row],[n]] -> a1 | F2: o1
A3: a | B3: 2 | C3: m2 | D3: =TTableCalc[[#This Row],[k]]&TTableCalc[[#This Row],[n]] -> a2 | F3: o2
A4: b | B4: 3 | C4: m3 | D4: =TTableCalc[[#This Row],[k]]&TTableCalc[[#This Row],[n]] -> b3 | F4: o3
A5: a | B5: 4 | C5: m4 | D5: =TTableCalc[[#This Row],[k]]&TTableCalc[[#This Row],[n]] -> a4 | F5: o4
A6: c | B6: 5 | C6: m5 | D6: =TTableCalc[[#This Row],[k]]&TTableCalc[[#This Row],[n]] -> c5 | F6: o5
A7: b | B7: 6 | C7: m6 | D7: =TTableCalc[[#This Row],[k]]&TTableCalc[[#This Row],[n]] -> b6 | F7: o6
A8: d | B8: 7 | C8: m7 | D8: =TTableCalc[[#This Row],[k]]&TTableCalc[[#This Row],[n]] -> d7 | F8: o7
A12: below | B12: =SUM(B2:B8) -> 28 | C12: =SUM(TTableCalc[n]) -> 28 | D12: =B5 -> 4

Sheet TableHidden
A1: k | B1: n | C1: m | E1: out
A2: a | B2: 1 | C2: m1 | E2: o1
A3: a | B3: 2 | C3: m2 | E3: o2
A4: b | B4: 3 | C4: m3 | E4: o3
A5: a | B5: 4 | C5: m4 | E5: o4
A6: c | B6: 5 | C6: m5 | E6: o5
A7: b | B7: 6 | C7: m6 | E7: o6
A8: d | B8: 7 | C8: m7 | E8: o7
A12: below | B12: =SUM(B2:B8) -> 28 | C12: =SUM(TTableHidden[n]) -> 28 | D12: =B5 -> 4

Sheet TableFiltered
A1: k | B1: n | C1: m | E1: out
A2: a | B2: 1 | C2: m1 | E2: o1
A3: a | B3: 2 | C3: m2 | E3: o2
A4: b | B4: 3 | C4: m3 | E4: o3
A5: a | B5: 4 | C5: m4 | E5: o4
A6: c | B6: 5 | C6: m5 | E6: o5
A7: b | B7: 6 | C7: m6 | E7: o6
A8: d | B8: 7 | C8: m7 | E8: o7
A12: below | B12: =SUM(B2:B8) -> 28 | C12: =SUM(TTableFiltered[n]) -> 28 | D12: =B5 -> 4

Sheet TableFilteredTotals
A1: k | B1: n | C1: m | E1: out
A2: a | B2: 1 | C2: m1 | E2: o1
A3: a | B3: 2 | C3: m2 | E3: o2
A4: b | B4: 3 | C4: m3 | E4: o3
A5: a | B5: 4 | C5: m4 | E5: o4
A6: c | B6: 5 | C6: m5 | E6: o5
A7: b | B7: 6 | C7: m6 | E7: o6
A8: d | B8: 7 | C8: m7 | E8: o7
A9: Total | B9: =SUBTOTAL(109,TTableFilteredTotals[n]) -> 10 | C9: =SUBTOTAL(103,TTableFilteredTotals[m]) -> 4
A12: below | B12: =SUM(B2:B8) -> 28 | C12: =SUM(TTableFilteredTotals[n]) -> 28 | D12: =B5 -> 4

Sheet TableHeadless
E1: out
A2: a | B2: 1 | C2: m1 | E2: o1
A3: a | B3: 2 | C3: m2 | E3: o2
A4: b | B4: 3 | C4: m3 | E4: o3
A5: a | B5: 4 | C5: m4 | E5: o4
A6: c | B6: 5 | C6: m5 | E6: o5
A7: b | B7: 6 | C7: m6 | E7: o6
A8: d | B8: 7 | C8: m7 | E8: o7
A12: below | B12: =SUM(B2:B8) -> 28 | C12: =SUM(TTableHeadless[n]) -> 28 | D12: =B5 -> 4

Sheet TableEmptyRows
A1: k | B1: n
A2: a | B2: 1
A3: b | B3: 2
A4: a | B4: 3
A5: c | B5: 4

Sheet TableLastSum
A1: k | B1: n
A2: a | B2: 1
A3: b | B3: 2
A4: a | B4: 3
A5: c | B5: 4
A6: z | B6: =SUM(B2:B5) -> 10

Sheet TableSorted
A1: k | B1: n | C1: m | E1: out
A2: a | B2: 1 | C2: m1 | E2: o1
A3: a | B3: 2 | C3: m2 | E3: o2
A4: b | B4: 3 | C4: m3 | E4: o3
A5: a | B5: 4 | C5: m4 | E5: o4
A6: c | B6: 5 | C6: m5 | E6: o5
A7: b | B7: 6 | C7: m6 | E7: o6
A8: d | B8: 7 | C8: m7 | E8: o7
A12: below | B12: =SUM(B2:B8) -> 28 | C12: =SUM(TTableSorted[n]) -> 28 | D12: =B5 -> 4

Sheet TableUnique
A1: k | B1: n | C1: m | E1: out
A2: a | B2: 1 | C2: m1 | E2: o1
A3: a | B3: 2 | C3: m2 | E3: o2
A4: b | B4: 3 | C4: m3 | E4: o3
A5: a | B5: 4 | C5: m4 | E5: o4
A6: c | B6: 5 | C6: m5 | E6: o5
A7: b | B7: 6 | C7: m6 | E7: o6
A8: d | B8: 7 | C8: m7 | E8: o7
A12: below | B12: =SUM(B2:B8) -> 28 | C12: =SUM(TTableUnique[n]) -> 28 | D12: =B5 -> 4

Sheet TableWider
A1: k | B1: n | C1: m | E1: out
A2: a | B2: 1 | C2: m1 | E2: o1
A3: a | B3: 2 | C3: m2 | E3: o2
A4: b | B4: 3 | C4: m3 | E4: o3
A5: a | B5: 4 | C5: m4 | E5: o4
A6: c | B6: 5 | C6: m5 | E6: o5
A7: b | B7: 6 | C7: m6 | E7: o6
A8: d | B8: 7 | C8: m7 | E8: o7
A12: below | B12: =SUM(B2:B8) -> 28 | C12: =SUM(TTableWider[n]) -> 28 | D12: =B5 -> 4

Sheet TableLonger
A1: k | B1: n | C1: m | E1: out
A2: a | B2: 1 | C2: m1 | E2: o1
A3: a | B3: 2 | C3: m2 | E3: o2
A4: b | B4: 3 | C4: m3 | E4: o3
A5: a | B5: 4 | C5: m4 | E5: o4
A6: c | B6: 5 | C6: m5 | E6: o5
A7: b | B7: 6 | C7: m6 | E7: o6
A8: d | B8: 7 | C8: m7 | E8: o7
A12: below | B12: =SUM(B2:B8) -> 28 | C12: =SUM(TTableLonger[n]) -> 28 | D12: =B5 -> 4
