Workbook

Sheet Data
A1: Region | B1: Product | C1: Year | D1: Qty | E1: Sales | F1: Day | H1: Team | I1: Person | J1: Score
A2: East | B2: Pen | C2: 2023 | D2: 3 | E2: 30 | F2: 44941 | H2: Red | I2: Ann | J2: 1
A3: East | B3: Ink | C3: 2023 | D3: 5 | E3: 50 | F3: 44977 | H3: Red | I3: Bob | J3: 2
A4: East | B4: Pen | C4: 2024 | D4: 2 | E4: 24 | F4: 45361 | H4: Blue | I4: Cat | J4: 4
A5: West | B5: Pen | C5: 2023 | D5: 4 | E5: 44 | F5: 45021 | H5: Blue | I5: Ann | J5: 8
A6: West | B6: Book | C6: 2024 | D6: 1 | E6: 120 | F6: 45418
A7: West | B7: Ink | C7: 2024 | D7: 6 | E7: 66 | F7: 45450
A8: North | B8: Book | C8: 2023 | D8: 2 | E8: 200 | F8: 45115
A9: North | B9: Pen | C9: 2024 | D9: 8 | E9: 88 | F9: 45513
A10: North | B10: Ink | C10: 2023 | D10: 7 | E10: 77 | F10: 45179
A11: South | B11: Book | C11: 2024 | D11: 3 | E11: 330 | F11: 45576
A12: South | B12: Pen | C12: 2023 | D12: 9 | E12: 99 | F12: 45242
A13: East | B13: Book | C13: 2024 | D13: 2 | E13: 220 | F13: 45639

Sheet PT1
A3: Row Labels | B3: Sum of Sales | E3: Row Labels | F3: Sum of Sales | J3: Sum of Sales | K3: Column Labels
A4: East | B4: 324 | E4: East | F4: 324 | J4: Row Labels | K4: 2023 | L4: 2024 | M4: Grand Total
A5: North | B5: 365 | E5: Book | F5: 220 | J5: East | K5: 80 | L5: 244 | M5: 324
A6: South | B6: 429 | E6: Ink | F6: 50 | J6: North | K6: 277 | L6: 88 | M6: 365
A7: West | B7: 230 | E7: Pen | F7: 54 | J7: South | K7: 99 | L7: 330 | M7: 429
A8: Grand Total | B8: 1348 | E8: North | F8: 365 | J8: West | K8: 44 | L8: 186 | M8: 230
E9: Book | F9: 200 | J9: Grand Total | K9: 500 | L9: 848 | M9: 1348
E10: Ink | F10: 77
E11: Pen | F11: 88
E12: South | F12: 429
E13: Book | F13: 330
E14: Pen | F14: 99
E15: West | F15: 230
E16: Book | F16: 120
E17: Ink | F17: 66
E18: Pen | F18: 44
E19: Grand Total | F19: 1348
B30: Column Labels | J30: Region | K30: Product | L30: Sum of Sales
B31: 2023 | D31: 2024 | F31: Total Sum of Sales | G31: Total Sum of Qty | J31: East | K31: Book | L31: 220
A32: Row Labels | B32: Sum of Sales | C32: Sum of Qty | D32: Sum of Sales | E32: Sum of Qty | K32: Ink | L32: 50
A33: East | B33: 80 | C33: 8 | D33: 244 | E33: 4 | F33: 324 | G33: 12 | K33: Pen | L33: 54
A34: North | B34: 277 | C34: 9 | D34: 88 | E34: 8 | F34: 365 | G34: 17 | J34: East Total | L34: 324
A35: South | B35: 99 | C35: 9 | D35: 330 | E35: 3 | F35: 429 | G35: 12 | J35: North | K35: Book | L35: 200
A36: West | B36: 44 | C36: 4 | D36: 186 | E36: 7 | F36: 230 | G36: 11 | K36: Ink | L36: 77
A37: Grand Total | B37: 500 | C37: 30 | D37: 848 | E37: 22 | F37: 1348 | G37: 52 | K37: Pen | L37: 88
J38: North Total | L38: 365
J39: South | K39: Book | L39: 330
K40: Pen | L40: 99
J41: South Total | L41: 429
J42: West | K42: Book | L42: 120
K43: Ink | L43: 66
K44: Pen | L44: 44
J45: West Total | L45: 230
J46: Grand Total | L46: 1348
A60: Year | B60: 2023
A62: Row Labels | B62: Sum of Sales | J62: Sum of Sales | K62: Column Labels
A63: Book | B63: 200 | J63: Row Labels | K63: 2023 | L63: 2024
A64: Ink | B64: 127 | J64: East | K64: 80 | L64: 244
A65: Pen | B65: 173 | J65: North | K65: 277 | L65: 88
A66: Grand Total | B66: 500 | J66: South | K66: 99 | L66: 330
...

Sheet PT2
A3: Sum of Sales | B3: Column Labels | J3: Region | K3: Product | L3: Sum of Sales
A4: Row Labels | B4: East | C4: North | D4: South | E4: West | F4: Grand Total | J4: East
A5: Book | B5: 220 | C5: 200 | D5: 330 | E5: 120 | F5: 870 | K5: Book | L5: 220
A6: Ink | B6: 50 | C6: 77 | E6: 66 | F6: 193 | K6: Ink | L6: 50
A7: Pen | B7: 54 | C7: 88 | D7: 99 | E7: 44 | F7: 285 | K7: Pen | L7: 54
A8: Grand Total | B8: 324 | C8: 365 | D8: 429 | E8: 230 | F8: 1348 | J8: East Total | L8: 324
J9: North
K10: Book | L10: 200
K11: Ink | L11: 77
K12: Pen | L12: 88
J13: North Total | L13: 365
J14: South
K15: Book | L15: 330
K16: Pen | L16: 99
J17: South Total | L17: 429
J18: West
K19: Book | L19: 120
K20: Ink | L20: 66
K21: Pen | L21: 44
J22: West Total | L22: 230
J23: Grand Total | L23: 1348
A30: Row Labels | B30: Sum of Sales | J30: Year | K30: (All)
A31: East
A32: Book | B32: 220 | J32: Row Labels | K32: Sum of Sales
A33: Ink | B33: 50 | J33: Book | K33: 870
A34: Pen | B34: 54 | J34: Ink | K34: 193
A35: North | J35: Pen | K35: 285
A36: Book | B36: 200 | J36: Grand Total | K36: 1348
A37: Ink | B37: 77
A38: Pen | B38: 88
A39: South
A40: Book | B40: 330
A41: Pen | B41: 99
A42: West
A43: Book | B43: 120
A44: Ink | B44: 66
A45: Pen | B45: 44
A46: Grand Total | B46: 1348
A60: Row Labels | B60: Sum of Qty | J60: Row Labels | K60: Sum of Sales | L60: Average of Sales
A61: 44941 | B61: 3 | J61: East | K61: 324 | L61: 81
...

Sheet PT3
A3: Row Labels | B3: Sum of Qty | J3: Row Labels | K3: Sum of Qty
A4: 2023 | B4: 30 | J4: 0-99 | K4: 44
A5: Jan | B5: 3 | J5: 100-199 | K5: 1
A6: Feb | B6: 5 | J6: 200-299 | K6: 4
A7: Apr | B7: 4 | J7: 300-399 | K7: 3
A8: Jul | B8: 2 | J8: Grand Total | K8: 52
A9: Sep | B9: 7
A10: Nov | B10: 9
A11: 2024 | B11: 22
A12: Mar | B12: 2
A13: May | B13: 1
A14: Jun | B14: 6
A15: Aug | B15: 8
A16: Oct | B16: 3
A17: Dec | B17: 2
A18: Grand Total | B18: 52
A40: Row Labels | B40: Sum of Profit | J40: Row Labels | K40: Share
A41: East | B41: 64.8 | J41: East | K41: 0.24035608
A42: North | B42: 73 | J42: North | K42: 0.27077151
A43: South | B43: 85.8 | J43: South | K43: 0.31824926
A44: West | B44: 46 | J44: West | K44: 0.17062315
A45: Grand Total | B45: 269.6 | J45: Grand Total | K45: 1
A60: Row Labels | B60: Sum of Score | K60: Column Labels
A61: Blue | B61: 12 | K61: Blue | M61: Blue Total | N61: Red | P61: Red Total | Q61: Grand Total
A62: Ann | B62: 8 | K62: Ann | L62: Cat | N62: Ann | O62: Bob
A63: Cat | B63: 4 | J63: Sum of Score | K63: 8 | L63: 4 | M63: 12 | N63: 1 | O63: 2 | P63: 3 | Q63: 15
A64: Red | B64: 3
A65: Ann | B65: 1
A66: Bob | B66: 2
A67: Grand Total | B67: 15
A75: Row Labels | B75: Sum of Score
A76: Blue
A77: Ann | B77: 8
A78: Cat | B78: 4
A79: Red
A80: Ann | B80: 1
A81: Bob | B81: 2
A82: Grand Total | B82: 15

Sheet Q
A1: =GETPIVOTDATA("Sales",'PT1'!$A$3) -> 1348
A2: =GETPIVOTDATA("Sum of Sales",'PT1'!$A$3,"Region","East") -> 324
A3: =GETPIVOTDATA("sales",'PT1'!$A$3,"region","east") -> 324
A4: =GETPIVOTDATA("Sales",'PT1'!$A$3,"Region","Nope") -> #REF!
A5: =GETPIVOTDATA("Qty",'PT1'!$A$3) -> #REF!
A6: =GETPIVOTDATA("Sales",'PT1'!$B$5) -> 1348
A7: =GETPIVOTDATA("Sales",'PT1'!$A$1) -> #REF!
A8: =GETPIVOTDATA("Sales",'PT1'!$A$3:$B$8,"Region","West") -> 230
A9: =GETPIVOTDATA("Sales",'PT1'!$E$3,"Region","East","Product","Pen") -> 54
A10: =GETPIVOTDATA("Sales",'PT1'!$E$3,"Product","Pen") -> #REF!
A11: =GETPIVOTDATA("Sales",'PT1'!$E$3,"Region","East") -> 324
A12: =GETPIVOTDATA("Sales",'PT1'!$E$3,"Product","Pen","Region","East") -> 54
A13: =GETPIVOTDATA("Sales",'PT1'!$J$3,"Year",2023) -> 500
A14: =GETPIVOTDATA("Sales",'PT1'!$J$3,"Year","2023") -> 500
A15: =GETPIVOTDATA("Sales",'PT1'!$J$3,"Region","East","Year",2024) -> 244
A16: =GETPIVOTDATA("Sales",'PT1'!$J$3,"Region","East") -> 324
A17: =GETPIVOTDATA("Sales",'PT1'!$J$3) -> 1348
A18: =GETPIVOTDATA("Sales",'PT1'!$A$30,"Region","East","Year",2024) -> 244
A19: =GETPIVOTDATA("Qty",'PT1'!$A$30,"Region","East","Year",2024) -> 4
A20: =GETPIVOTDATA("Sum of Qty",'PT1'!$A$30,"Year",2023) -> 30
A21: =GETPIVOTDATA("Qty",'PT1'!$A$30) -> 52
A22: =GETPIVOTDATA("Sales",'PT1'!$J$30,"Region","East","Product","Ink") -> 50
A23: =GETPIVOTDATA("Sales",'PT1'!$J$30,"Region","West") -> 230
A24: =GETPIVOTDATA("Sales",'PT1'!$J$30) -> 1348
A25: =GETPIVOTDATA("Sales",'PT1'!$A$62,"Product","Pen") -> 173
A26: =GETPIVOTDATA("Sales",'PT1'!$A$62,"Year",2023) -> 500
A27: =GETPIVOTDATA("Sales",'PT1'!$A$62,"Year",2024) -> #REF!
A28: =GETPIVOTDATA("Sales",'PT1'!$A$62,"Year",2023,"Product","Ink") -> 127
A29: =GETPIVOTDATA("Sales",'PT1'!$A$62) -> 500
A30: =GETPIVOTDATA("Sales",'PT1'!$J$62,"Region","East","Year",2023) -> 80
A31: =GETPIVOTDATA("Sales",'PT1'!$J$62,"Region","East") -> #REF!
A32: =GETPIVOTDATA("Sales",'PT1'!$J$62) -> #REF!
A33: =GETPIVOTDATA("Sales",'PT1'!$A$80,"Region","North") -> 365
A34: =GETPIVOTDATA("Count of Product",'PT1'!$A$80,"Region","North") -> 3
A35: =GETPIVOTDATA("Product",'PT1'!$A$80) -> 12
A36: =GETPIVOTDATA("Revenue",'PT1'!$J$80,"Region","Orient") -> 324
A37: =GETPIVOTDATA("Revenue",'PT1'!$J$80,"Region","East") -> 324
A38: =GETPIVOTDATA("Sales",'PT1'!$J$80) -> 1348
A39: =GETPIVOTDATA("Sum of Sales",'PT1'!$J$80) -> #REF!
A40: =GETPIVOTDATA("Qty",'PT1'!$A$105,"Year",2024) -> 22
...
